[2022-05-28 17:54:02,278] {taskinstance.py:1043} INFO - Dependencies all met for <TaskInstance: quotation_dag.fetch_quotation_from_AAPL scheduled__2022-05-28T15:53:00+00:00 [queued]>
[2022-05-28 17:54:02,281] {taskinstance.py:1043} INFO - Dependencies all met for <TaskInstance: quotation_dag.fetch_quotation_from_AAPL scheduled__2022-05-28T15:53:00+00:00 [queued]>
[2022-05-28 17:54:02,281] {taskinstance.py:1249} INFO - 
--------------------------------------------------------------------------------
[2022-05-28 17:54:02,282] {taskinstance.py:1250} INFO - Starting attempt 1 of 2
[2022-05-28 17:54:02,282] {taskinstance.py:1251} INFO - 
--------------------------------------------------------------------------------
[2022-05-28 17:54:02,296] {taskinstance.py:1270} INFO - Executing <Task(PythonOperator): fetch_quotation_from_AAPL> on 2022-05-28 15:53:00+00:00
[2022-05-28 17:54:02,298] {standard_task_runner.py:52} INFO - Started process 19010 to run task
[2022-05-28 17:54:02,300] {standard_task_runner.py:79} INFO - Running: ['airflow', 'tasks', 'run', 'quotation_dag', 'fetch_quotation_from_AAPL', 'scheduled__2022-05-28T15:53:00+00:00', '--job-id', '144', '--raw', '--subdir', 'DAGS_FOLDER/load_quotation_dag.py', '--cfg-path', '/tmp/tmpdrjozy3g', '--error-file', '/tmp/tmp5vumzpc7']
[2022-05-28 17:54:02,300] {standard_task_runner.py:80} INFO - Job 144: Subtask fetch_quotation_from_AAPL
[2022-05-28 17:54:02,329] {logging_mixin.py:109} INFO - Running <TaskInstance: quotation_dag.fetch_quotation_from_AAPL scheduled__2022-05-28T15:53:00+00:00 [running]> on host DESKTOP-O4M0F04.localdomain
[2022-05-28 17:54:02,366] {taskinstance.py:1446} INFO - Exporting the following env vars:
AIRFLOW_CTX_DAG_EMAIL=airflow@example.com
AIRFLOW_CTX_DAG_OWNER=airflow
AIRFLOW_CTX_DAG_ID=quotation_dag
AIRFLOW_CTX_TASK_ID=fetch_quotation_from_AAPL
AIRFLOW_CTX_EXECUTION_DATE=2022-05-28T15:53:00+00:00
AIRFLOW_CTX_DAG_RUN_ID=scheduled__2022-05-28T15:53:00+00:00
[2022-05-28 17:54:02,367] {taskinstance.py:1774} ERROR - Task failed with exception
Traceback (most recent call last):
  File "/home/udimini/airflow_venv/airflow_venv/lib/python3.8/site-packages/airflow/operators/python.py", line 174, in execute
    return_value = self.execute_callable()
  File "/home/udimini/airflow_venv/airflow_venv/lib/python3.8/site-packages/airflow/operators/python.py", line 188, in execute_callable
    return self.python_callable(*self.op_args, **self.op_kwargs)
TypeError: fetch_quotation_from_big_finance() missing 2 required positional arguments: 'date_from' and 'date_to'
[2022-05-28 17:54:02,370] {taskinstance.py:1278} INFO - Marking task as UP_FOR_RETRY. dag_id=quotation_dag, task_id=fetch_quotation_from_AAPL, execution_date=20220528T155300, start_date=20220528T155402, end_date=20220528T155402
[2022-05-28 17:54:02,383] {standard_task_runner.py:93} ERROR - Failed to execute job 144 for task fetch_quotation_from_AAPL (fetch_quotation_from_big_finance() missing 2 required positional arguments: 'date_from' and 'date_to'; 19010)
[2022-05-28 17:54:02,392] {local_task_job.py:154} INFO - Task exited with return code 1
[2022-05-28 17:54:02,403] {local_task_job.py:264} INFO - 0 downstream tasks scheduled from follow-on schedule check
