[2022-05-28 19:25:55,283] {taskinstance.py:1043} INFO - Dependencies all met for <TaskInstance: social_sentiment_dag.fetch_social_sentiment_from_AAPL manual__2022-05-28T17:25:05+00:00 [queued]>
[2022-05-28 19:25:55,288] {taskinstance.py:1043} INFO - Dependencies all met for <TaskInstance: social_sentiment_dag.fetch_social_sentiment_from_AAPL manual__2022-05-28T17:25:05+00:00 [queued]>
[2022-05-28 19:25:55,288] {taskinstance.py:1249} INFO - 
--------------------------------------------------------------------------------
[2022-05-28 19:25:55,288] {taskinstance.py:1250} INFO - Starting attempt 1 of 2
[2022-05-28 19:25:55,288] {taskinstance.py:1251} INFO - 
--------------------------------------------------------------------------------
[2022-05-28 19:25:55,300] {taskinstance.py:1270} INFO - Executing <Task(PythonOperator): fetch_social_sentiment_from_AAPL> on 2022-05-28 17:25:05+00:00
[2022-05-28 19:25:55,301] {standard_task_runner.py:52} INFO - Started process 28888 to run task
[2022-05-28 19:25:55,304] {standard_task_runner.py:79} INFO - Running: ['airflow', 'tasks', 'run', 'social_sentiment_dag', 'fetch_social_sentiment_from_AAPL', 'manual__2022-05-28T17:25:05+00:00', '--job-id', '229', '--raw', '--subdir', 'DAGS_FOLDER/load_social_sentiment_dag.py', '--cfg-path', '/tmp/tmpg6jw8wfb', '--error-file', '/tmp/tmpeue_8_al']
[2022-05-28 19:25:55,305] {standard_task_runner.py:80} INFO - Job 229: Subtask fetch_social_sentiment_from_AAPL
[2022-05-28 19:25:55,337] {logging_mixin.py:109} INFO - Running <TaskInstance: social_sentiment_dag.fetch_social_sentiment_from_AAPL manual__2022-05-28T17:25:05+00:00 [running]> on host DESKTOP-O4M0F04.localdomain
[2022-05-28 19:25:55,371] {taskinstance.py:1446} INFO - Exporting the following env vars:
AIRFLOW_CTX_DAG_EMAIL=airflow@example.com
AIRFLOW_CTX_DAG_OWNER=airflow
AIRFLOW_CTX_DAG_ID=social_sentiment_dag
AIRFLOW_CTX_TASK_ID=fetch_social_sentiment_from_AAPL
AIRFLOW_CTX_EXECUTION_DATE=2022-05-28T17:25:05+00:00
AIRFLOW_CTX_DAG_RUN_ID=manual__2022-05-28T17:25:05+00:00
[2022-05-28 19:25:55,470] {logging_mixin.py:109} INFO - Successful connection to mongo db
[2022-05-28 19:25:55,901] {taskinstance.py:1774} ERROR - Task failed with exception
Traceback (most recent call last):
  File "/home/udimini/airflow_venv/airflow_venv/lib/python3.8/site-packages/requests/models.py", line 910, in json
    return complexjson.loads(self.text, **kwargs)
  File "/usr/lib/python3.8/json/__init__.py", line 357, in loads
    return _default_decoder.decode(s)
  File "/usr/lib/python3.8/json/decoder.py", line 337, in decode
    obj, end = self.raw_decode(s, idx=_w(s, 0).end())
  File "/usr/lib/python3.8/json/decoder.py", line 355, in raw_decode
    raise JSONDecodeError("Expecting value", s, err.value) from None
json.decoder.JSONDecodeError: Expecting value: line 2 column 1 (char 1)

During handling of the above exception, another exception occurred:

Traceback (most recent call last):
  File "/home/udimini/airflow_venv/airflow_venv/lib/python3.8/site-packages/airflow/operators/python.py", line 174, in execute
    return_value = self.execute_callable()
  File "/home/udimini/airflow_venv/airflow_venv/lib/python3.8/site-packages/airflow/operators/python.py", line 188, in execute_callable
    return self.python_callable(*self.op_args, **self.op_kwargs)
  File "/home/udimini/airflow/dags/load_social_sentiment_dag.py", line 24, in push_social_sentiment_on_datalake
    sentiments = fetch_social_sentiment_from_big_finance(company, date_from, date_to)
  File "/home/udimini/airflow/dags/load_social_sentiment_dag.py", line 14, in fetch_social_sentiment_from_big_finance
    response = get(f"https://bigfinance-api.herokuapp.com/finnhub/api/v1/sociale-sentiment/{company}/{date_from}/{date_to}/", headers=header).json()
  File "/home/udimini/airflow_venv/airflow_venv/lib/python3.8/site-packages/requests/models.py", line 917, in json
    raise RequestsJSONDecodeError(e.msg, e.doc, e.pos)
requests.exceptions.JSONDecodeError: [Errno Expecting value] 
<!doctype html>
<html lang="en">
<head>
  <title>Not Found</title>
</head>
<body>
  <h1>Not Found</h1><p>The requested resource was not found on this server.</p>
</body>
</html>
: 1
[2022-05-28 19:25:55,912] {taskinstance.py:1278} INFO - Marking task as UP_FOR_RETRY. dag_id=social_sentiment_dag, task_id=fetch_social_sentiment_from_AAPL, execution_date=20220528T172505, start_date=20220528T172555, end_date=20220528T172555
[2022-05-28 19:25:55,929] {standard_task_runner.py:93} ERROR - Failed to execute job 229 for task fetch_social_sentiment_from_AAPL ([Errno Expecting value] 
<!doctype html>
<html lang="en">
<head>
  <title>Not Found</title>
</head>
<body>
  <h1>Not Found</h1><p>The requested resource was not found on this server.</p>
</body>
</html>
: 1; 28888)
[2022-05-28 19:25:55,960] {local_task_job.py:154} INFO - Task exited with return code 1
[2022-05-28 19:25:55,989] {local_task_job.py:264} INFO - 0 downstream tasks scheduled from follow-on schedule check
