[2022-05-11 11:20:06,309] {taskinstance.py:1043} INFO - Dependencies all met for <TaskInstance: big_finance_dag.fetch_data_from_big_finance scheduled__2022-05-11T09:19:00+00:00 [queued]>
[2022-05-11 11:20:06,313] {taskinstance.py:1043} INFO - Dependencies all met for <TaskInstance: big_finance_dag.fetch_data_from_big_finance scheduled__2022-05-11T09:19:00+00:00 [queued]>
[2022-05-11 11:20:06,313] {taskinstance.py:1249} INFO - 
--------------------------------------------------------------------------------
[2022-05-11 11:20:06,313] {taskinstance.py:1250} INFO - Starting attempt 1 of 2
[2022-05-11 11:20:06,313] {taskinstance.py:1251} INFO - 
--------------------------------------------------------------------------------
[2022-05-11 11:20:06,325] {taskinstance.py:1270} INFO - Executing <Task(PythonOperator): fetch_data_from_big_finance> on 2022-05-11 09:19:00+00:00
[2022-05-11 11:20:06,326] {standard_task_runner.py:52} INFO - Started process 5266 to run task
[2022-05-11 11:20:06,328] {standard_task_runner.py:79} INFO - Running: ['airflow', 'tasks', 'run', 'big_finance_dag', 'fetch_data_from_big_finance', 'scheduled__2022-05-11T09:19:00+00:00', '--job-id', '15', '--raw', '--subdir', 'DAGS_FOLDER/big_finance_dag.py', '--cfg-path', '/tmp/tmprwlidnow', '--error-file', '/tmp/tmppwxkqg04']
[2022-05-11 11:20:06,328] {standard_task_runner.py:80} INFO - Job 15: Subtask fetch_data_from_big_finance
[2022-05-11 11:20:06,365] {logging_mixin.py:109} INFO - Running <TaskInstance: big_finance_dag.fetch_data_from_big_finance scheduled__2022-05-11T09:19:00+00:00 [running]> on host DESKTOP-O4M0F04.localdomain
[2022-05-11 11:20:06,400] {taskinstance.py:1446} INFO - Exporting the following env vars:
AIRFLOW_CTX_DAG_EMAIL=airflow@example.com
AIRFLOW_CTX_DAG_OWNER=airflow
AIRFLOW_CTX_DAG_ID=big_finance_dag
AIRFLOW_CTX_TASK_ID=fetch_data_from_big_finance
AIRFLOW_CTX_EXECUTION_DATE=2022-05-11T09:19:00+00:00
AIRFLOW_CTX_DAG_RUN_ID=scheduled__2022-05-11T09:19:00+00:00
[2022-05-11 11:20:06,401] {taskinstance.py:1774} ERROR - Task failed with exception
Traceback (most recent call last):
  File "/home/udimini/airflow_venv/airflow_venv/lib/python3.8/site-packages/airflow/operators/python.py", line 174, in execute
    return_value = self.execute_callable()
  File "/home/udimini/airflow_venv/airflow_venv/lib/python3.8/site-packages/airflow/operators/python.py", line 188, in execute_callable
    return self.python_callable(*self.op_args, **self.op_kwargs)
TypeError: fetch_data_from_big_finance() missing 1 required positional argument: 'company'
[2022-05-11 11:20:06,406] {taskinstance.py:1278} INFO - Marking task as UP_FOR_RETRY. dag_id=big_finance_dag, task_id=fetch_data_from_big_finance, execution_date=20220511T091900, start_date=20220511T092006, end_date=20220511T092006
[2022-05-11 11:20:06,417] {standard_task_runner.py:93} ERROR - Failed to execute job 15 for task fetch_data_from_big_finance (fetch_data_from_big_finance() missing 1 required positional argument: 'company'; 5266)
[2022-05-11 11:20:06,460] {local_task_job.py:154} INFO - Task exited with return code 1
[2022-05-11 11:20:06,469] {local_task_job.py:264} INFO - 0 downstream tasks scheduled from follow-on schedule check
