[2022-05-31 10:13:51,179] {taskinstance.py:1160} INFO - Dependencies all met for <TaskInstance: quotation_dag.fetch_quotation_from_GOOGL scheduled__2022-05-30T08:13:35.149493+00:00 [queued]>
[2022-05-31 10:13:51,185] {taskinstance.py:1160} INFO - Dependencies all met for <TaskInstance: quotation_dag.fetch_quotation_from_GOOGL scheduled__2022-05-30T08:13:35.149493+00:00 [queued]>
[2022-05-31 10:13:51,185] {taskinstance.py:1357} INFO - 
--------------------------------------------------------------------------------
[2022-05-31 10:13:51,185] {taskinstance.py:1358} INFO - Starting attempt 1 of 2
[2022-05-31 10:13:51,185] {taskinstance.py:1359} INFO - 
--------------------------------------------------------------------------------
[2022-05-31 10:13:51,200] {taskinstance.py:1378} INFO - Executing <Task(PythonOperator): fetch_quotation_from_GOOGL> on 2022-05-30 08:13:35.149493+00:00
[2022-05-31 10:13:51,203] {standard_task_runner.py:52} INFO - Started process 22091 to run task
[2022-05-31 10:13:51,208] {standard_task_runner.py:79} INFO - Running: ['airflow', 'tasks', 'run', 'quotation_dag', 'fetch_quotation_from_GOOGL', 'scheduled__2022-05-30T08:13:35.149493+00:00', '--job-id', '4', '--raw', '--subdir', 'DAGS_FOLDER/load_quotation_dag.py', '--cfg-path', '/tmp/tmpxdbqn84x', '--error-file', '/tmp/tmpr7ul1r2h']
[2022-05-31 10:13:51,208] {standard_task_runner.py:80} INFO - Job 4: Subtask fetch_quotation_from_GOOGL
[2022-05-31 10:13:51,227] {logging_mixin.py:115} WARNING - /home/udimini/airflow_venv/lib/python3.8/site-packages/airflow/configuration.py:529 DeprecationWarning: The sql_alchemy_conn option in [core] has been moved to the sql_alchemy_conn option in [database] - the old setting has been used, but please update your config.
[2022-05-31 10:13:51,229] {logging_mixin.py:115} WARNING - /home/udimini/airflow_venv/lib/python3.8/site-packages/airflow/configuration.py:529 DeprecationWarning: The sql_engine_encoding option in [core] has been moved to the sql_engine_encoding option in [database] - the old setting has been used, but please update your config.
[2022-05-31 10:13:51,251] {task_command.py:370} INFO - Running <TaskInstance: quotation_dag.fetch_quotation_from_GOOGL scheduled__2022-05-30T08:13:35.149493+00:00 [running]> on host DESKTOP-O4M0F04.localdomain
[2022-05-31 10:13:51,305] {taskinstance.py:1570} INFO - Exporting the following env vars:
AIRFLOW_CTX_DAG_EMAIL=airflow@example.com
AIRFLOW_CTX_DAG_OWNER=airflow
AIRFLOW_CTX_DAG_ID=quotation_dag
AIRFLOW_CTX_TASK_ID=fetch_quotation_from_GOOGL
AIRFLOW_CTX_EXECUTION_DATE=2022-05-30T08:13:35.149493+00:00
AIRFLOW_CTX_TRY_NUMBER=1
AIRFLOW_CTX_DAG_RUN_ID=scheduled__2022-05-30T08:13:35.149493+00:00
[2022-05-31 10:13:51,324] {logging_mixin.py:115} INFO - Successful connection to mongo db
[2022-05-31 10:13:52,497] {taskinstance.py:1890} ERROR - Task failed with exception
Traceback (most recent call last):
  File "/home/udimini/airflow_venv/lib/python3.8/site-packages/requests/models.py", line 910, in json
    return complexjson.loads(self.text, **kwargs)
  File "/usr/lib/python3.8/json/__init__.py", line 357, in loads
    return _default_decoder.decode(s)
  File "/usr/lib/python3.8/json/decoder.py", line 337, in decode
    obj, end = self.raw_decode(s, idx=_w(s, 0).end())
  File "/usr/lib/python3.8/json/decoder.py", line 355, in raw_decode
    raise JSONDecodeError("Expecting value", s, err.value) from None
json.decoder.JSONDecodeError: Expecting value: line 2 column 1 (char 1)

During handling of the above exception, another exception occurred:

Traceback (most recent call last):
  File "/home/udimini/airflow_venv/lib/python3.8/site-packages/airflow/operators/python.py", line 171, in execute
    return_value = self.execute_callable()
  File "/home/udimini/airflow_venv/lib/python3.8/site-packages/airflow/operators/python.py", line 189, in execute_callable
    return self.python_callable(*self.op_args, **self.op_kwargs)
  File "/home/udimini/airflow/dags/load_quotation_dag.py", line 24, in push_quotation_on_datalake
    quotation = fetch_quotation_from_big_finance(company, date_from, date_to)
  File "/home/udimini/airflow/dags/load_quotation_dag.py", line 14, in fetch_quotation_from_big_finance
    response = get(f"https://bigfinance-api.herokuapp.com/stockdata/api/v1/intraday/{company}/{date_from}/{date_to}/", headers=header).json()
  File "/home/udimini/airflow_venv/lib/python3.8/site-packages/requests/models.py", line 917, in json
    raise RequestsJSONDecodeError(e.msg, e.doc, e.pos)
requests.exceptions.JSONDecodeError: [Errno Expecting value] 
<!doctype html>
<html lang="en">
<head>
  <title>Server Error (500)</title>
</head>
<body>
  <h1>Server Error (500)</h1><p></p>
</body>
</html>
: 1
[2022-05-31 10:13:52,501] {taskinstance.py:1396} INFO - Marking task as UP_FOR_RETRY. dag_id=quotation_dag, task_id=fetch_quotation_from_GOOGL, execution_date=20220530T081335, start_date=20220531T081351, end_date=20220531T081352
[2022-05-31 10:13:52,515] {standard_task_runner.py:92} ERROR - Failed to execute job 4 for task fetch_quotation_from_GOOGL ([Errno Expecting value] 
<!doctype html>
<html lang="en">
<head>
  <title>Server Error (500)</title>
</head>
<body>
  <h1>Server Error (500)</h1><p></p>
</body>
</html>
: 1; 22091)
[2022-05-31 10:13:52,542] {local_task_job.py:156} INFO - Task exited with return code 1
[2022-05-31 10:13:52,557] {local_task_job.py:273} INFO - 0 downstream tasks scheduled from follow-on schedule check
