[2022-05-28 17:56:02,350] {taskinstance.py:1043} INFO - Dependencies all met for <TaskInstance: quotation_dag.fetch_quotation_from_AAPL scheduled__2022-05-28T15:55:00+00:00 [queued]>
[2022-05-28 17:56:02,356] {taskinstance.py:1043} INFO - Dependencies all met for <TaskInstance: quotation_dag.fetch_quotation_from_AAPL scheduled__2022-05-28T15:55:00+00:00 [queued]>
[2022-05-28 17:56:02,356] {taskinstance.py:1249} INFO - 
--------------------------------------------------------------------------------
[2022-05-28 17:56:02,356] {taskinstance.py:1250} INFO - Starting attempt 1 of 2
[2022-05-28 17:56:02,356] {taskinstance.py:1251} INFO - 
--------------------------------------------------------------------------------
[2022-05-28 17:56:02,368] {taskinstance.py:1270} INFO - Executing <Task(PythonOperator): fetch_quotation_from_AAPL> on 2022-05-28 15:55:00+00:00
[2022-05-28 17:56:02,369] {standard_task_runner.py:52} INFO - Started process 19495 to run task
[2022-05-28 17:56:02,372] {standard_task_runner.py:79} INFO - Running: ['airflow', 'tasks', 'run', 'quotation_dag', 'fetch_quotation_from_AAPL', 'scheduled__2022-05-28T15:55:00+00:00', '--job-id', '150', '--raw', '--subdir', 'DAGS_FOLDER/load_quotation_dag.py', '--cfg-path', '/tmp/tmpz1oga36f', '--error-file', '/tmp/tmpl0xkue_o']
[2022-05-28 17:56:02,373] {standard_task_runner.py:80} INFO - Job 150: Subtask fetch_quotation_from_AAPL
[2022-05-28 17:56:02,411] {logging_mixin.py:109} INFO - Running <TaskInstance: quotation_dag.fetch_quotation_from_AAPL scheduled__2022-05-28T15:55:00+00:00 [running]> on host DESKTOP-O4M0F04.localdomain
[2022-05-28 17:56:02,459] {taskinstance.py:1446} INFO - Exporting the following env vars:
AIRFLOW_CTX_DAG_EMAIL=airflow@example.com
AIRFLOW_CTX_DAG_OWNER=airflow
AIRFLOW_CTX_DAG_ID=quotation_dag
AIRFLOW_CTX_TASK_ID=fetch_quotation_from_AAPL
AIRFLOW_CTX_EXECUTION_DATE=2022-05-28T15:55:00+00:00
AIRFLOW_CTX_DAG_RUN_ID=scheduled__2022-05-28T15:55:00+00:00
[2022-05-28 17:56:02,459] {taskinstance.py:1774} ERROR - Task failed with exception
Traceback (most recent call last):
  File "/home/udimini/airflow_venv/airflow_venv/lib/python3.8/site-packages/airflow/operators/python.py", line 174, in execute
    return_value = self.execute_callable()
  File "/home/udimini/airflow_venv/airflow_venv/lib/python3.8/site-packages/airflow/operators/python.py", line 188, in execute_callable
    return self.python_callable(*self.op_args, **self.op_kwargs)
  File "/home/udimini/airflow/dags/load_quotation_dag.py", line 16, in fetch_quotation_from_big_finance
    response = get(f"https://bigfinance-api.herokuapp.com/stockdata/api/v1/intraday/{company}/{date_from}/{date_to}/", headers=header).json()
NameError: name 'date_to' is not defined
[2022-05-28 17:56:02,464] {taskinstance.py:1278} INFO - Marking task as UP_FOR_RETRY. dag_id=quotation_dag, task_id=fetch_quotation_from_AAPL, execution_date=20220528T155500, start_date=20220528T155602, end_date=20220528T155602
[2022-05-28 17:56:02,476] {standard_task_runner.py:93} ERROR - Failed to execute job 150 for task fetch_quotation_from_AAPL (name 'date_to' is not defined; 19495)
[2022-05-28 17:56:02,504] {local_task_job.py:154} INFO - Task exited with return code 1
[2022-05-28 17:56:02,519] {local_task_job.py:264} INFO - 0 downstream tasks scheduled from follow-on schedule check
