[2022-05-11 11:12:03,621] {taskinstance.py:1043} INFO - Dependencies all met for <TaskInstance: big_finance_dag.fetch_data_from_big_finance scheduled__2022-05-11T09:11:00+00:00 [queued]>
[2022-05-11 11:12:03,625] {taskinstance.py:1043} INFO - Dependencies all met for <TaskInstance: big_finance_dag.fetch_data_from_big_finance scheduled__2022-05-11T09:11:00+00:00 [queued]>
[2022-05-11 11:12:03,625] {taskinstance.py:1249} INFO - 
--------------------------------------------------------------------------------
[2022-05-11 11:12:03,625] {taskinstance.py:1250} INFO - Starting attempt 1 of 2
[2022-05-11 11:12:03,625] {taskinstance.py:1251} INFO - 
--------------------------------------------------------------------------------
[2022-05-11 11:12:03,637] {taskinstance.py:1270} INFO - Executing <Task(PythonOperator): fetch_data_from_big_finance> on 2022-05-11 09:11:00+00:00
[2022-05-11 11:12:03,638] {standard_task_runner.py:52} INFO - Started process 4246 to run task
[2022-05-11 11:12:03,640] {standard_task_runner.py:79} INFO - Running: ['airflow', 'tasks', 'run', 'big_finance_dag', 'fetch_data_from_big_finance', 'scheduled__2022-05-11T09:11:00+00:00', '--job-id', '12', '--raw', '--subdir', 'DAGS_FOLDER/big_finance_dag.py', '--cfg-path', '/tmp/tmp2pifv9_b', '--error-file', '/tmp/tmpj9fcvtuf']
[2022-05-11 11:12:03,641] {standard_task_runner.py:80} INFO - Job 12: Subtask fetch_data_from_big_finance
[2022-05-11 11:12:03,671] {logging_mixin.py:109} INFO - Running <TaskInstance: big_finance_dag.fetch_data_from_big_finance scheduled__2022-05-11T09:11:00+00:00 [running]> on host DESKTOP-O4M0F04.localdomain
[2022-05-11 11:12:03,706] {taskinstance.py:1446} INFO - Exporting the following env vars:
AIRFLOW_CTX_DAG_EMAIL=airflow@example.com
AIRFLOW_CTX_DAG_OWNER=airflow
AIRFLOW_CTX_DAG_ID=big_finance_dag
AIRFLOW_CTX_TASK_ID=fetch_data_from_big_finance
AIRFLOW_CTX_EXECUTION_DATE=2022-05-11T09:11:00+00:00
AIRFLOW_CTX_DAG_RUN_ID=scheduled__2022-05-11T09:11:00+00:00
[2022-05-11 11:12:03,707] {taskinstance.py:1774} ERROR - Task failed with exception
Traceback (most recent call last):
  File "/home/udimini/airflow_venv/airflow_venv/lib/python3.8/site-packages/airflow/operators/python.py", line 174, in execute
    return_value = self.execute_callable()
  File "/home/udimini/airflow_venv/airflow_venv/lib/python3.8/site-packages/airflow/operators/python.py", line 188, in execute_callable
    return self.python_callable(*self.op_args, **self.op_kwargs)
TypeError: fetch_data_from_big_finance() missing 1 required positional argument: 'company'
[2022-05-11 11:12:03,710] {taskinstance.py:1278} INFO - Marking task as UP_FOR_RETRY. dag_id=big_finance_dag, task_id=fetch_data_from_big_finance, execution_date=20220511T091100, start_date=20220511T091203, end_date=20220511T091203
[2022-05-11 11:12:03,723] {standard_task_runner.py:93} ERROR - Failed to execute job 12 for task fetch_data_from_big_finance (fetch_data_from_big_finance() missing 1 required positional argument: 'company'; 4246)
[2022-05-11 11:12:03,732] {local_task_job.py:154} INFO - Task exited with return code 1
[2022-05-11 11:12:03,741] {local_task_job.py:264} INFO - 0 downstream tasks scheduled from follow-on schedule check
